<?xml version="1.0" ?>
<!-- =================================================================================== -->
<!-- |    This document was autogenerated by xacro from /home/rosubuntu/eurobot_ws/src/eurobot_description/urdf/mon_robot.urdf.xacro | -->
<!-- |    EDITING THIS FILE BY HAND IS NOT RECOMMENDED                                 | -->
<!-- =================================================================================== -->
<robot name="mon_robot_mecanum">
  <material name="green">
    <color rgba="0.2 1 0.2 1"/>
  </material>
  <material name="black">
    <color rgba="0 0 0 1"/>
  </material>
  <material name="silver">
    <color rgba="0.8 0.8 0.8 1"/>
  </material>
  <material name="yellow">
    <color rgba="1 0.92 0.016 1"/>
  </material>
  <material name="blue">
    <color rgba="0 0 1 1"/>
  </material>
  <!-- Lien 'world' qui est le parent de tous les autres liens -->
  <link name="world_link"/>
  <!-- Joint fixe pour connecter la base au monde -->
  <joint name="base_joint" type="fixed">
    <origin rpy="0 0 0" xyz="1 1 0"/>
    <parent link="world_link"/>
    <child link="base_link"/>
  </joint>
  <link name="base_link">
    <visual>
      <geometry>
        <box size="0.2 0.25 0.003"/>
      </geometry>
      <origin rpy="0 0 0" xyz="0 0 0.0505"/>
      <!-- This will insert the origin block -->
      <material name="green"/>
      <!--penser à bien mettre le xacro materials avant-->
    </visual>
    <collision>
      <geometry>
        <box size="0.2 0.25 0.003"/>
        <origin rpy="0 0 0" xyz="0 0 0.0505"/>
      </geometry>
    </collision>
    <inertial>
      <origin rpy="0 0 0" xyz="0 0 0.0505"/>
      <mass value="0.4"/>
      <inertia ixx="0.0020836333333333333" ixy="0.0" ixz="0.0" iyy="0.0013336333333333337" iyz="0.0" izz="0.003416666666666667"/>
    </inertial>
  </link>
  <gazebo reference="base_link">
    <material>Gazebo/Green</material>
  </gazebo>
  <!-- LiDAR Joint -->
  <joint name="LiDAR_joint" type="fixed">
    <parent link="base_link"/>
    <child link="LiDAR_link"/>
    <origin rpy="0 0 0" xyz="0 0 0.0565"/>
  </joint>
  <!-- LiDAR Link -->
  <link name="LiDAR_link">
    <visual>
      <origin rpy="0 0 0" xyz="0 0 0"/>
      <geometry>
        <cylinder length="0.015" radius="0.028"/>
        <!-- dimensions -->
      </geometry>
      <material name="yellow"/>
    </visual>
    <collision>
      <origin rpy="0 0 0" xyz="0 0 0"/>
      <geometry>
        <cylinder length="0.015" radius="0.028"/>
        <!-- dimensions -->
      </geometry>
    </collision>
    <inertial>
      <origin rpy="0 0 0" xyz="0.0 0 0"/>
      <mass value="0.1"/>
      <inertia ixx="2.1475000000000004e-05" ixy="0.0" ixz="0.0" iyy="2.1475000000000004e-05" iyz="0.0" izz="3.9200000000000004e-05"/>
    </inertial>
  </link>
  <!-- Simulation du LiDAR -->
  <gazebo reference="LiDAR_link">
    <material>Gazebo/Yellow</material>
    <sensor name="laser" type="ray">
      <pose> 0 0 0 0 0 0 </pose>
      <visualize>true</visualize>
      <update_rate>10</update_rate>
      <ray>
        <scan>
          <horizontal>
            <samples>360</samples>
            <resolution>1</resolution>
            <min_angle>-3.14</min_angle>
            <max_angle>3.14</max_angle>
          </horizontal>
        </scan>
        <range>
          <min>0.3</min>
          <max>12</max>
          <resolution>0.01</resolution>
        </range>
      </ray>
      <plugin filename="libgazebo_ros_ray_sensor.so" name="laser_controller">
        <ros>
          <argument>~/out:=scan</argument>
          <!-- publishing ont the topic scan -->
        </ros>
        <output_type>sensor_msg/LaserScan</output_type>
      </plugin>
    </sensor>
  </gazebo>
  <!-- Joint to connect the mecanum wheel to a robot (you will need to adjust this) -->
  <joint name="roue_AvG_joint" type="continuous">
    <parent link="base_link"/>
    <child link="roue_AvG_link"/>
    <origin rpy="0 1.5707963267948966 0" xyz="-0.1225 0.0825 0.0325"/>
    <!-- This will insert the origin block -->
    <axis xyz="0 1 0"/>
    <!-- Axis of rotation for the wheel -->
  </joint>
  <!-- Mecanum Wheel Link -->
  <link name="roue_AvG_link">
    <visual>
      <origin rpy="0 0 0" xyz="0 0 0"/>
      <geometry>
        <cylinder length="0.043" radius="0.0325"/>
        <!-- dimensions -->
      </geometry>
      <material name="black"/>
    </visual>
    <collision>
      <origin rpy="0 0 0" xyz="0 0 0"/>
      <geometry>
        <cylinder length="0.043" radius="0.0325"/>
        <!-- dimensions -->
      </geometry>
    </collision>
    <inertial>
      <origin rpy="0 0 0" xyz="0 0 0"/>
      <mass value="0.1"/>
      <inertia ixx="4.181458333333333e-05" ixy="0.0" ixz="0.0" iyy="4.181458333333333e-05" iyz="0.0" izz="5.281250000000001e-05"/>
    </inertial>
  </link>
  <gazebo reference="roue_AvG_link">
    <material>Gazebo/Black</material>
    <mu1 value="1"/>
    <!-- Coef de friction statique -->
    <mu2 value="0.8"/>
    <!-- Coef de friction cinétique -->
  </gazebo>
  <!-- Joint to connect the mecanum wheel to a robot (you will need to adjust this) -->
  <joint name="roue_AvD_joint" type="continuous">
    <parent link="base_link"/>
    <child link="roue_AvD_link"/>
    <origin rpy="0 1.5707963267948966 0" xyz="0.1225 0.0825 0.0325"/>
    <!-- This will insert the origin block -->
    <axis xyz="0 1 0"/>
    <!-- Axis of rotation for the wheel -->
  </joint>
  <!-- Mecanum Wheel Link -->
  <link name="roue_AvD_link">
    <visual>
      <origin rpy="0 0 0" xyz="0 0 0"/>
      <geometry>
        <cylinder length="0.043" radius="0.0325"/>
        <!-- dimensions -->
      </geometry>
      <material name="black"/>
    </visual>
    <collision>
      <origin rpy="0 0 0" xyz="0 0 0"/>
      <geometry>
        <cylinder length="0.043" radius="0.0325"/>
        <!-- dimensions -->
      </geometry>
    </collision>
    <inertial>
      <origin rpy="0 0 0" xyz="0 0 0"/>
      <mass value="0.1"/>
      <inertia ixx="4.181458333333333e-05" ixy="0.0" ixz="0.0" iyy="4.181458333333333e-05" iyz="0.0" izz="5.281250000000001e-05"/>
    </inertial>
  </link>
  <gazebo reference="roue_AvD_link">
    <material>Gazebo/Black</material>
    <mu1 value="1"/>
    <!-- Coef de friction statique -->
    <mu2 value="0.8"/>
    <!-- Coef de friction cinétique -->
  </gazebo>
  <!-- Joint to connect the mecanum wheel to a robot (you will need to adjust this) -->
  <joint name="roue_ArG_joint" type="continuous">
    <parent link="base_link"/>
    <child link="roue_ArG_link"/>
    <origin rpy="0 1.5707963267948966 0" xyz="-0.1225 -0.0825 0.0325"/>
    <!-- This will insert the origin block -->
    <axis xyz="0 1 0"/>
    <!-- Axis of rotation for the wheel -->
  </joint>
  <!-- Mecanum Wheel Link -->
  <link name="roue_ArG_link">
    <visual>
      <origin rpy="0 0 0" xyz="0 0 0"/>
      <geometry>
        <cylinder length="0.043" radius="0.0325"/>
        <!-- dimensions -->
      </geometry>
      <material name="black"/>
    </visual>
    <collision>
      <origin rpy="0 0 0" xyz="0 0 0"/>
      <geometry>
        <cylinder length="0.043" radius="0.0325"/>
        <!-- dimensions -->
      </geometry>
    </collision>
    <inertial>
      <origin rpy="0 0 0" xyz="0 0 0"/>
      <mass value="0.1"/>
      <inertia ixx="4.181458333333333e-05" ixy="0.0" ixz="0.0" iyy="4.181458333333333e-05" iyz="0.0" izz="5.281250000000001e-05"/>
    </inertial>
  </link>
  <gazebo reference="roue_ArG_link">
    <material>Gazebo/Black</material>
    <mu1 value="1"/>
    <!-- Coef de friction statique -->
    <mu2 value="0.8"/>
    <!-- Coef de friction cinétique -->
  </gazebo>
  <!-- Joint to connect the mecanum wheel to a robot (you will need to adjust this) -->
  <joint name="roue_ArD_joint" type="continuous">
    <parent link="base_link"/>
    <child link="roue_ArD_link"/>
    <origin rpy="0 1.5707963267948966 0" xyz="0.1225 -0.0825 0.0325"/>
    <!-- This will insert the origin block -->
    <axis xyz="0 1 0"/>
    <!-- Axis of rotation for the wheel -->
  </joint>
  <!-- Mecanum Wheel Link -->
  <link name="roue_ArD_link">
    <visual>
      <origin rpy="0 0 0" xyz="0 0 0"/>
      <geometry>
        <cylinder length="0.043" radius="0.0325"/>
        <!-- dimensions -->
      </geometry>
      <material name="black"/>
    </visual>
    <collision>
      <origin rpy="0 0 0" xyz="0 0 0"/>
      <geometry>
        <cylinder length="0.043" radius="0.0325"/>
        <!-- dimensions -->
      </geometry>
    </collision>
    <inertial>
      <origin rpy="0 0 0" xyz="0 0 0"/>
      <mass value="0.1"/>
      <inertia ixx="4.181458333333333e-05" ixy="0.0" ixz="0.0" iyy="4.181458333333333e-05" iyz="0.0" izz="5.281250000000001e-05"/>
    </inertial>
  </link>
  <gazebo reference="roue_ArD_link">
    <material>Gazebo/Black</material>
    <mu1 value="1"/>
    <!-- Coef de friction statique -->
    <mu2 value="0.8"/>
    <!-- Coef de friction cinétique -->
  </gazebo>
  <!-- Tiges Joint -->
  <joint name="tige_AvG_joint" type="fixed">
    <parent link="base_link"/>
    <child link="tige_AvG_link"/>
    <origin rpy="0 0 0" xyz="0.09 0.115 0.10200000000000001"/>
    <!-- This will insert the origin block -->
  </joint>
  <!-- Tiges Link -->
  <link name="tige_AvG_link">
    <visual>
      <origin rpy="0 0 0" xyz="0 0 0"/>
      <geometry>
        <cylinder length="0.1" radius="0.005"/>
        <!-- dimensions -->
      </geometry>
      <material name="silver"/>
    </visual>
    <collision>
      <origin rpy="0 0 0" xyz="0 0 0"/>
      <geometry>
        <cylinder length="0.1" radius="0.005"/>
        <!-- dimensions -->
      </geometry>
    </collision>
    <inertial>
      <origin rpy="0 0 0" xyz="0 0 0"/>
      <mass value="0.01"/>
      <!-- Example mass à modifier-->
      <inertia ixx="0.001" ixy="0" ixz="0" iyy="0.001" iyz="0" izz="0.002"/>
      <!-- Example inertia tensor values (à calculer) -->
    </inertial>
    <inertial>
      <origin rpy="0 0 0" xyz="0 0 0"/>
      <mass value="0.01"/>
      <inertia ixx="8.395833333333335e-06" ixy="0.0" ixz="0.0" iyy="8.395833333333335e-06" iyz="0.0" izz="1.2500000000000002e-07"/>
    </inertial>
  </link>
  <gazebo reference="tige_AvG_link">
    <material>Gazebo/Silver</material>
  </gazebo>
  <!-- Tiges Joint -->
  <joint name="tige_AvD_joint" type="fixed">
    <parent link="base_link"/>
    <child link="tige_AvD_link"/>
    <origin rpy="0 0 0" xyz="-0.09 0.115 0.10200000000000001"/>
    <!-- This will insert the origin block -->
  </joint>
  <!-- Tiges Link -->
  <link name="tige_AvD_link">
    <visual>
      <origin rpy="0 0 0" xyz="0 0 0"/>
      <geometry>
        <cylinder length="0.1" radius="0.005"/>
        <!-- dimensions -->
      </geometry>
      <material name="silver"/>
    </visual>
    <collision>
      <origin rpy="0 0 0" xyz="0 0 0"/>
      <geometry>
        <cylinder length="0.1" radius="0.005"/>
        <!-- dimensions -->
      </geometry>
    </collision>
    <inertial>
      <origin rpy="0 0 0" xyz="0 0 0"/>
      <mass value="0.01"/>
      <!-- Example mass à modifier-->
      <inertia ixx="0.001" ixy="0" ixz="0" iyy="0.001" iyz="0" izz="0.002"/>
      <!-- Example inertia tensor values (à calculer) -->
    </inertial>
    <inertial>
      <origin rpy="0 0 0" xyz="0 0 0"/>
      <mass value="0.01"/>
      <inertia ixx="8.395833333333335e-06" ixy="0.0" ixz="0.0" iyy="8.395833333333335e-06" iyz="0.0" izz="1.2500000000000002e-07"/>
    </inertial>
  </link>
  <gazebo reference="tige_AvD_link">
    <material>Gazebo/Silver</material>
  </gazebo>
  <!-- Tiges Joint -->
  <joint name="tige_ArG_joint" type="fixed">
    <parent link="base_link"/>
    <child link="tige_ArG_link"/>
    <origin rpy="0 0 0" xyz="0.09 -0.115 0.10200000000000001"/>
    <!-- This will insert the origin block -->
  </joint>
  <!-- Tiges Link -->
  <link name="tige_ArG_link">
    <visual>
      <origin rpy="0 0 0" xyz="0 0 0"/>
      <geometry>
        <cylinder length="0.1" radius="0.005"/>
        <!-- dimensions -->
      </geometry>
      <material name="silver"/>
    </visual>
    <collision>
      <origin rpy="0 0 0" xyz="0 0 0"/>
      <geometry>
        <cylinder length="0.1" radius="0.005"/>
        <!-- dimensions -->
      </geometry>
    </collision>
    <inertial>
      <origin rpy="0 0 0" xyz="0 0 0"/>
      <mass value="0.01"/>
      <!-- Example mass à modifier-->
      <inertia ixx="0.001" ixy="0" ixz="0" iyy="0.001" iyz="0" izz="0.002"/>
      <!-- Example inertia tensor values (à calculer) -->
    </inertial>
    <inertial>
      <origin rpy="0 0 0" xyz="0 0 0"/>
      <mass value="0.01"/>
      <inertia ixx="8.395833333333335e-06" ixy="0.0" ixz="0.0" iyy="8.395833333333335e-06" iyz="0.0" izz="1.2500000000000002e-07"/>
    </inertial>
  </link>
  <gazebo reference="tige_ArG_link">
    <material>Gazebo/Silver</material>
  </gazebo>
  <!-- Tiges Joint -->
  <joint name="tige_ArD_joint" type="fixed">
    <parent link="base_link"/>
    <child link="tige_ArD_link"/>
    <origin rpy="0 0 0" xyz="-0.09 -0.115 0.10200000000000001"/>
    <!-- This will insert the origin block -->
  </joint>
  <!-- Tiges Link -->
  <link name="tige_ArD_link">
    <visual>
      <origin rpy="0 0 0" xyz="0 0 0"/>
      <geometry>
        <cylinder length="0.1" radius="0.005"/>
        <!-- dimensions -->
      </geometry>
      <material name="silver"/>
    </visual>
    <collision>
      <origin rpy="0 0 0" xyz="0 0 0"/>
      <geometry>
        <cylinder length="0.1" radius="0.005"/>
        <!-- dimensions -->
      </geometry>
    </collision>
    <inertial>
      <origin rpy="0 0 0" xyz="0 0 0"/>
      <mass value="0.01"/>
      <!-- Example mass à modifier-->
      <inertia ixx="0.001" ixy="0" ixz="0" iyy="0.001" iyz="0" izz="0.002"/>
      <!-- Example inertia tensor values (à calculer) -->
    </inertial>
    <inertial>
      <origin rpy="0 0 0" xyz="0 0 0"/>
      <mass value="0.01"/>
      <inertia ixx="8.395833333333335e-06" ixy="0.0" ixz="0.0" iyy="8.395833333333335e-06" iyz="0.0" izz="1.2500000000000002e-07"/>
    </inertial>
  </link>
  <gazebo reference="tige_ArD_link">
    <material>Gazebo/Silver</material>
  </gazebo>
  <link name="plateau2_link">
    <visual>
      <geometry>
        <box size="0.2 0.25 0.003"/>
      </geometry>
      <origin rpy="0 0 0" xyz="0 0 0.15350000000000003"/>
      <!-- This will insert the origin block -->
      <material name="green"/>
      <!--penser à bien mettre le xacro materials avant-->
    </visual>
    <collision>
      <geometry>
        <box size="0.2 0.25 0.003"/>
        <origin rpy="0 0 0" xyz="0 0 0.15350000000000003"/>
      </geometry>
    </collision>
    <inertial>
      <origin rpy="0 0 0" xyz="0 0 0.15350000000000003"/>
      <mass value="0.4"/>
      <inertia ixx="0.0020836333333333333" ixy="0.0" ixz="0.0" iyy="0.0013336333333333337" iyz="0.0" izz="0.003416666666666667"/>
    </inertial>
  </link>
  <gazebo reference="plateau2_link">
    <material>Gazebo/Green</material>
  </gazebo>
  <joint name="plateau2_joint" type="fixed">
    <origin rpy="0 0 0" xyz="0 0 0"/>
    <parent link="base_link"/>
    <child link="plateau2_link"/>
  </joint>
  <joint name="camera_joint" type="fixed">
    <origin rpy="0 0 0" xyz="0 0.105 0.137"/>
    <parent link="plateau2_link"/>
    <child link="camera_link"/>
  </joint>
  <link name="camera_link">
    <visual>
      <origin rpy="0 0 0" xyz="0 0 0"/>
      <geometry>
        <box size="0.03 0.02 0.03"/>
      </geometry>
      <material name="blue"/>
    </visual>
    <visual>
      <origin rpy="1.5707963267948966 0 0" xyz="0 0.015 0"/>
      <geometry>
        <cylinder length="0.01" radius="0.01"/>
      </geometry>
      <material name="blue"/>
    </visual>
    <collision>
      <origin rpy="0 0 0" xyz="0.0 0 0"/>
      <!-- attention j'ai rien modif à partir de la -->
      <geometry>
        <box size="0.03 0.03 0.03"/>
      </geometry>
    </collision>
    <inertial>
      <origin rpy="0 0 0" xyz="0.0 0 0"/>
      <mass value="0.05"/>
      <inertia ixx="5.416666666666667e-06" ixy="0.0" ixz="0.0" iyy="7.499999999999999e-06" iyz="0.0" izz="5.416666666666667e-06"/>
    </inertial>
  </link>
  <gazebo reference="camera_link">
    <material>Gazebo/Blue</material>
  </gazebo>
</robot>
